Workbook
Name Types: Списки!$A$2:$A$7
Name Currencies: Списки!$B$2:$B$7
Name Materials: Списки!$C$2:$C$10
Name Construction: Списки!$D$2:$D$5
Name Commercial: Списки!$E$2:$E$5
Name Purpose: Списки!$F$2:$F$6
Name YesNo: Списки!$G$2:$G$3
Name DebtFormats: Списки!$H$2:$H$3
Name Goals: Списки!$I$2:$I$8

Sheet Сводка
A1: Сбор объектов по вариантам покупки
A2: Одна строка — один объект. Справа на листе видно, чего не хватает для публикации в форме добавления.
A4: Вариант | B4: В таблице | C4: Можно публиковать | D4: Не хватает | E4: Что проверяет лист
A5: Купить сейчас | B5: =COUNTIF('Купить сейчас'!AO3:AO82,"<>") | C5: =COUNTIF('Купить сейчас'!AO3:AO82,"Можно публиковать") | D5: =COUNTIF('Купить сейчас'!AO3:AO82,"Не хватает") | E5: Формат «Аукцион + Продать сейчас»: фиксированная цена, минимальная цена, стартовая ставка, даты и документы.
A6: Аукцион | B6: =COUNTIF('Аукцион'!AO3:AO82,"<>") | C6: =COUNTIF('Аукцион'!AO3:AO82,"Можно публиковать") | D6: =COUNTIF('Аукцион'!AO3:AO82,"Не хватает") | E6: Торги без обязательной цены «Продать сейчас». Минимальная цена, ставка и срок аукциона обязательны.
A7: Доли | B7: =COUNTIF('Доли'!AK3:AK82,"<>") | C7: =COUNTIF('Доли'!AK3:AK82,"Можно публиковать") | D7: =COUNTIF('Доли'!AK3:AK82,"Не хватает") | E7: Общая стоимость и число долей. Цена одной доли считается сама. Тест-драйва в этом формате нет.
A8: Долги | B8: =COUNTIF('Долги'!AQ3:AQ82,"<>") | C8: =COUNTIF('Долги'!AQ3:AQ82,"Можно публиковать") | D8: =COUNTIF('Долги'!AQ3:AQ82,"Не хватает") | E8: Сумма долга. Аукционные поля включаются только если формат — «Долги + Аукцион». Пакет долга желателен, но не блокирует.
A9: Девелопмент | B9: =COUNTIF('Девелопмент'!AV3:AV82,"<>") | C9: =COUNTIF('Девелопмент'!AV3:AV82,"Можно публиковать") | D9: =COUNTIF('Девелопмент'!AV3:AV82,"Не хватает") | E9: Адрес и параметры объекта плюс экономика проекта. Бюджет и прибыль считаются сами.
A11: Как читать таблицу
A12: Поля совпадают с мастером добавления объекта. Обязательность параметров зависит от типа недвижимости.
A13: Квартира и апартаменты: площадь, жилая площадь, комнаты, ванные, этаж, этажность, год и материал.
A14: Дом и вилла: участок, площадь дома, спальни, ванные, этажность, год и материал.
A15: Коммерция: площадь и тип. Земля: участок и назначение.
A16: Для всех вариантов, кроме долгов, нужны документ о праве собственности и справка об отсутствии обременений. Фото — минимум одно.
A17: «Продать сейчас»: минимальная цена не выше самой цены и не выше 90% от неё. Стартовая ставка не выше 30%. Аукцион длится минимум 3 месяца и 15 дней.
A18: «Желательно добрать» не мешает публикации: это описание, кадастр, видео, меньше пяти фото и рекомендованный пакет долга.
A19: Формулы протянуты на 80 строк. Если объектов больше, потяните последнюю заполненную строку вниз.
A20: Комментарий к заголовку колонки объясняет, когда поле обязательно. Лист «Списки» скрыт и питает выпадающие списки.

Sheet Купить сейчас
A1: Сбор | B1: Объект | D1: Адрес | I1: Объект | J1: Параметры | W1: Цена | AB1: Тест-драйв | AE1: Подача | AJ1: Документы | AM1: Проверка
A2: Источник | B2: Название | C2: Тип недвижимости | D2: Страна | E2: Город | F2: Улица | G2: Номер дома | H2: Кадастровый номер | I2: Валюта | J2: Площадь, м² | K2: Жилая, м² | L2: Участок, м² | M2: Комнаты | N2: Спальни | O2: Ванные | P2: Этаж | Q2: Этажей | R2: Год | S2: Материал | T2: Конструкция | U2: Тип коммерции | V2: Назначение земли | W2: Продать сейчас | X2: Минимальная цена | Y2: Стартовая ставка | Z2: Начало аукциона | AA2: Окончание аукциона | AB2: Тест-драйв | AC2: Сутки тест-драйва | AD2: Депозит тест-драйва | AE2: Фото, шт. | AF2: Ссылка на фото | AG2: Ссылка на видео | AH2: Описание | AI2: Удобства | AJ2: Право собственности | AK2: Нет обременений | AL2: Доп. документы | AM2: Не хватает для публикации | AN2: Желательно добрать | AO2: Готовность
AM3: =IF(NOT(COUNTA(A3:AL3)>0),"",IF(TEXTJOIN(", ",TRUE,IF(B3="","Название",""),IF(C3="","Тип недвижимости",""),IF(D3="","Страна",""),IF(E3="","Город",""),IF(F3="","Улица",""),IF(I3="","Валюта",""),IF(OR(AE3="",AE3<1),"Хотя бы 1 фото",""),IF(AND(OR(C3="Квартира",C3="Апартаменты",C3="Дом",C3="Вилла",C3="Коммерческая"),J3=""),"Площадь",""),IF(AND(OR(C3="Квартира",C3="Апартаменты"),K3=""),"Жилая площадь",""),IF(AND(OR(C3="Дом",C3="Вилла",C3="Земля"),L3=""),"Площадь участка",""),IF(AND(OR(C3="Квартира",C3="Апартаменты"),M3=""),"Комнаты",""),IF(AND(OR(C3="Дом",C3="Вилла"),N3=""),"Спальни",""),IF(AND(OR(C3="Квартира",C3="Апартаменты",C3="Дом",C3="Вилла"),O3=""),"Ванные",""),IF(AND(OR(C3="Квартира",C3="Апартаменты"),P3=""),"Этаж",""),IF(AND(OR(OR(C3="Квартира",C3="Апартаменты"),OR(C3="Дом",C3="Вилла")),Q3=""),"Этажей",""),IF(AND(OR(OR(C3="Квартира",C3="Апартаменты"),OR(C3="Дом",C3="Вилла")),OR(R3="",R3>YEAR(TODAY()))),"Год постройки",""),IF(AND(P3<>"",Q3<>"",P3>Q3),"Этаж больше этажности",""),IF(AND(OR(C3="Квартира",C3="Апартаменты",C3="Дом",C3="Вилла"),S3=""),"Материал",""),IF(AND(OR(C3="Коммерческая"),U3=""),"Тип коммерции",""),IF(AND(OR(C3="Земля"),V3=""),"Назначение земли",""),IF(OR(W3="",W3<=0),"Продать сейчас",""),IF(OR(X3="",X3<=0),"Минимальная цена продажи",""),IF(OR(Y3="",Y3<=0),"Стартовая ставка",""),IF(Z3="","Начало аукциона",""),IF(AA3="","Окончание аукциона",""),IF(AND(W3<>"",X3<>"",X3>W3),"Минимальная цена выше «Продать сейчас»",""),IF(AND(W3<>"",X3<>"",X3<=W3,X3>W3*0.9),"Минимальная цена выше 90% от «Продать сейчас»",""),IF(AND(W3<>"",Y3<>"",Y3>W3*0.3),"Стартовая ставка выше 30% от «Продать сейчас»",""),IF(AND(Z3<>"",AA3<>"",AA3<EDATE(Z3,3)+15),"Аукцион короче 3 месяцев и 15 дней",""),IF(AND(AB3="Да",OR(AC3="",AC3<=0)),"Цена тест-драйва за сутки",""),IF(OR(AJ3="",AJ3="Нет"),"Право собственности",""),IF(OR(AK3="",AK3="Нет"),"Справка об отсутствии обременений",""))="","",TEXTJOIN(", ",TRUE,IF(B3="","Название",""),IF(C3="","Тип недвижимости",""),IF(D3="","Страна",""),IF(E3="","Город",""),IF(F3="","Улица",""),IF(I3="","Валюта",""),IF(OR(AE3="",AE3<1),"Хотя бы 1 фото",""),IF(AND(OR(C3="Квартира",C3="Апартаменты",C3="Дом",C3="Вилла",C3="Коммерческая"),J3=""),"Площадь",""),IF(AND(OR(C3="Квартира",C3="Апартаменты"),K3=""),"Жилая площадь",""),IF(AND(OR(C3="Дом",C3="Вилла",C3="Земля"),L3=""),"Площадь участка",""),IF(AND(OR(C3="Квартира",C3="Апартаменты"),M3=""),"Комнаты",""),IF(AND(OR(C3="Дом",C3="Вилла"),N3=""),"Спальни",""),IF(AND(OR(C3="Квартира",C3="Апартаменты",C3="Дом",C3="Вилла"),O3=""),"Ванные",""),IF(AND(OR(C3="Квартира",C3="Апартаменты"),P3=""),"Этаж",""),IF(AND(OR(OR(C3="Квартира",C3="Апартаменты"),OR(C3="Дом",C3="Вилла")),Q3=""),"Этажей",""),IF(AND(OR(OR(C3="Квартира",C3="Апартаменты"),OR(C3="Дом",C3="Вилла")),OR(R3="",R3>YEAR(TODAY()))),"Год постройки",""),IF(AND(P3<>"",Q3<>"",P3>Q3),"Этаж больше этажности",""),IF(AND(OR(C3="Квартира",C3="Апартаменты",C3="Дом",C3="Вилла"),S3=""),"Материал",""),IF(AND(OR(C3="Коммерческая"),U3=""),"Тип коммерции",""),IF(AND(OR(C3="Земля"),V3=""),"Назначение земли",""),IF(OR(W3="",W3<=0),"Продать сейчас",""),IF(OR(X3="",X3<=0),"Минимальная цена продажи",""),IF(OR(Y3="",Y3<=0),"Стартовая ставка",""),IF(Z3="","Начало аукциона",""),IF(AA3="","Окончание аукциона",""),IF(AND(W3<>"",X3<>"",X3>W3),"Минимальная цена выше «Продать сейчас»",""),IF(AND(W3<>"",X3<>"",X3<=W3,X3>W3*0.9),"Минимальная цена выше 90% от «Продать сейчас»",""),IF(AND(W3<>"",Y3<>"",Y3>W3*0.3),"Стартовая ставка выше 30% от «Продать сейчас»",""),IF(AND(Z3<>"",AA3<>"",AA3<EDATE(Z3,3)+15),"Аукцион короче 3 месяцев и 15 дней",""),IF(AND(AB3="Да",OR(AC3="",AC3<=0)),"Цена тест-драйва за сутки",""),IF(OR(AJ3="",AJ3="Нет"),"Право собственности",""),IF(OR(AK3="",AK3="Нет"),"Справка об отсутствии обременений","")))) | AN3: =IF(NOT(COUNTA(A3:AL3)>0),"",IF(TEXTJOIN(", ",TRUE,IF(AH3="","Описание",""),IF(AND(AE3<>"",AE3>=1,AE3<5),"Фото меньше 5",""),IF(AG3="","Видео",""),IF(H3="","Кадастровый номер",""),IF(AF3="","Ссылка на фото",""))="","",TEXTJOIN(", ",TRUE,IF(AH3="","Описание",""),IF(AND(AE3<>"",AE3>=1,AE3<5),"Фото меньше 5",""),IF(AG3="","Видео",""),IF(H3="","Кадастровый номер",""),IF(AF3="","Ссылка на фото","")))) | AO3: =IF(NOT(COUNTA(A3:AL3)>0),"",IF(AM3="","Можно публиковать","Не хватает"))
AM4: =IF(NOT(COUNTA(A4:AL4)>0),"",IF(TEXTJOIN(", ",TRUE,IF(B4="","Название",""),IF(C4="","Тип недвижимости",""),IF(D4="","Страна",""),IF(E4="","Город",""),IF(F4="","Улица",""),IF(I4="","Валюта",""),IF(OR(AE4="",AE4<1),"Хотя бы 1 фото",""),IF(AND(OR(C4="Квартира",C4="Апартаменты",C4="Дом",C4="Вилла",C4="Коммерческая"),J4=""),"Площадь",""),IF(AND(OR(C4="Квартира",C4="Апартаменты"),K4=""),"Жилая площадь",""),IF(AND(OR(C4="Дом",C4="Вилла",C4="Земля"),L4=""),"Площадь участка",""),IF(AND(OR(C4="Квартира",C4="Апартаменты"),M4=""),"Комнаты",""),IF(AND(OR(C4="Дом",C4="Вилла"),N4=""),"Спальни",""),IF(AND(OR(C4="Квартира",C4="Апартаменты",C4="Дом",C4="Вилла"),O4=""),"Ванные",""),IF(AND(OR(C4="Квартира",C4="Апартаменты"),P4=""),"Этаж",""),IF(AND(OR(OR(C4="Квартира",C4="Апартаменты"),OR(C4="Дом",C4="Вилла")),Q4=""),"Этажей",""),IF(AND(OR(OR(C4="Квартира",C4="Апартаменты"),OR(C4="Дом",C4="Вилла")),OR(R4="",R4>YEAR(TODAY()))),"Год постройки",""),IF(AND(P4<>"",Q4<>"",P4>Q4),"Этаж больше этажности",""),IF(AND(OR(C4="Квартира",C4="Апартаменты",C4="Дом",C4="Вилла"),S4=""),"Материал",""),IF(AND(OR(C4="Коммерческая"),U4=""),"Тип коммерции",""),IF(AND(OR(C4="Земля"),V4=""),"Назначение земли",""),IF(OR(W4="",W4<=0),"Продать сейчас",""),IF(OR(X4="",X4<=0),"Минимальная цена продажи",""),IF(OR(Y4="",Y4<=0),"Стартовая ставка",""),IF(Z4="","Начало аукциона",""),IF(AA4="","Окончание аукциона",""),IF(AND(W4<>"",X4<>"",X4>W4),"Минимальная цена выше «Продать сейчас»",""),IF(AND(W4<>"",X4<>"",X4<=W4,X4>W4*0.9),"Минимальная цена выше 90% от «Продать сейчас»",""),IF(AND(W4<>"",Y4<>"",Y4>W4*0.3),"Стартовая ставка выше 30% от «Продать сейчас»",""),IF(AND(Z4<>"",AA4<>"",AA4<EDATE(Z4,3)+15),"Аукцион короче 3 месяцев и 15 дней",""),IF(AND(AB4="Да",OR(AC4="",AC4<=0)),"Цена тест-драйва за сутки",""),IF(OR(AJ4="",AJ4="Нет"),"Право собственности",""),IF(OR(AK4="",AK4="Нет"),"Справка об отсутствии обременений",""))="","",TEXTJOIN(", ",TRUE,IF(B4="","Название",""),IF(C4="","Тип недвижимости",""),IF(D4="","Страна",""),IF(E4="","Город",""),IF(F4="","Улица",""),IF(I4="","Валюта",""),IF(OR(AE4="",AE4<1),"Хотя бы 1 фото",""),IF(AND(OR(C4="Квартира",C4="Апартаменты",C4="Дом",C4="Вилла",C4="Коммерческая"),J4=""),"Площадь",""),IF(AND(OR(C4="Квартира",C4="Апартаменты"),K4=""),"Жилая площадь",""),IF(AND(OR(C4="Дом",C4="Вилла",C4="Земля"),L4=""),"Площадь участка",""),IF(AND(OR(C4="Квартира",C4="Апартаменты"),M4=""),"Комнаты",""),IF(AND(OR(C4="Дом",C4="Вилла"),N4=""),"Спальни",""),IF(AND(OR(C4="Квартира",C4="Апартаменты",C4="Дом",C4="Вилла"),O4=""),"Ванные",""),IF(AND(OR(C4="Квартира",C4="Апартаменты"),P4=""),"Этаж",""),IF(AND(OR(OR(C4="Квартира",C4="Апартаменты"),OR(C4="Дом",C4="Вилла")),Q4=""),"Этажей",""),IF(AND(OR(OR(C4="Квартира",C4="Апартаменты"),OR(C4="Дом",C4="Вилла")),OR(R4="",R4>YEAR(TODAY()))),"Год постройки",""),IF(AND(P4<>"",Q4<>"",P4>Q4),"Этаж больше этажности",""),IF(AND(OR(C4="Квартира",C4="Апартаменты",C4="Дом",C4="Вилла"),S4=""),"Материал",""),IF(AND(OR(C4="Коммерческая"),U4=""),"Тип коммерции",""),IF(AND(OR(C4="Земля"),V4=""),"Назначение земли",""),IF(OR(W4="",W4<=0),"Продать сейчас",""),IF(OR(X4="",X4<=0),"Минимальная цена продажи",""),IF(OR(Y4="",Y4<=0),"Стартовая ставка",""),IF(Z4="","Начало аукциона",""),IF(AA4="","Окончание аукциона",""),IF(AND(W4<>"",X4<>"",X4>W4),"Минимальная цена выше «Продать сейчас»",""),IF(AND(W4<>"",X4<>"",X4<=W4,X4>W4*0.9),"Минимальная цена выше 90% от «Продать сейчас»",""),IF(AND(W4<>"",Y4<>"",Y4>W4*0.3),"Стартовая ставка выше 30% от «Продать сейчас»",""),IF(AND(Z4<>"",AA4<>"",AA4<EDATE(Z4,3)+15),"Аукцион короче 3 месяцев и 15 дней",""),IF(AND(AB4="Да",OR(AC4="",AC4<=0)),"Цена тест-драйва за сутки",""),IF(OR(AJ4="",AJ4="Нет"),"Право собственности",""),IF(OR(AK4="",AK4="Нет"),"Справка об отсутствии обременений","")))) | AN4: =IF(NOT(COUNTA(A4:AL4)>0),"",IF(TEXTJOIN(", ",TRUE,IF(AH4="","Описание",""),IF(AND(AE4<>"",AE4>=1,AE4<5),"Фото меньше 5",""),IF(AG4="","Видео",""),IF(H4="","Кадастровый номер",""),IF(AF4="","Ссылка на фото",""))="","",TEXTJOIN(", ",TRUE,IF(AH4="","Описание",""),IF(AND(AE4<>"",AE4>=1,AE4<5),"Фото меньше 5",""),IF(AG4="","Видео",""),IF(H4="","Кадастровый номер",""),IF(AF4="","Ссылка на фото","")))) | AO4: =IF(NOT(COUNTA(A4:AL4)>0),"",IF(AM4="","Можно публиковать","Не хватает"))
AM5: =IF(NOT(COUNTA(A5:AL5)>0),"",IF(TEXTJOIN(", ",TRUE,IF(B5="","Название",""),IF(C5="","Тип недвижимости",""),IF(D5="","Страна",""),IF(E5="","Город",""),IF(F5="","Улица",""),IF(I5="","Валюта",""),IF(OR(AE5="",AE5<1),"Хотя бы 1 фото",""),IF(AND(OR(C5="Квартира",C5="Апартаменты",C5="Дом",C5="Вилла",C5="Коммерческая"),J5=""),"Площадь",""),IF(AND(OR(C5="Квартира",C5="Апартаменты"),K5=""),"Жилая площадь",""),IF(AND(OR(C5="Дом",C5="Вилла",C5="Земля"),L5=""),"Площадь участка",""),IF(AND(OR(C5="Квартира",C5="Апартаменты"),M5=""),"Комнаты",""),IF(AND(OR(C5="Дом",C5="Вилла"),N5=""),"Спальни",""),IF(AND(OR(C5="Квартира",C5="Апартаменты",C5="Дом",C5="Вилла"),O5=""),"Ванные",""),IF(AND(OR(C5="Квартира",C5="Апартаменты"),P5=""),"Этаж",""),IF(AND(OR(OR(C5="Квартира",C5="Апартаменты"),OR(C5="Дом",C5="Вилла")),Q5=""),"Этажей",""),IF(AND(OR(OR(C5="Квартира",C5="Апартаменты"),OR(C5="Дом",C5="Вилла")),OR(R5="",R5>YEAR(TODAY()))),"Год постройки",""),IF(AND(P5<>"",Q5<>"",P5>Q5),"Этаж больше этажности",""),IF(AND(OR(C5="Квартира",C5="Апартаменты",C5="Дом",C5="Вилла"),S5=""),"Материал",""),IF(AND(OR(C5="Коммерческая"),U5=""),"Тип коммерции",""),IF(AND(OR(C5="Земля"),V5=""),"Назначение земли",""),IF(OR(W5="",W5<=0),"Продать сейчас",""),IF(OR(X5="",X5<=0),"Минимальная цена продажи",""),IF(OR(Y5="",Y5<=0),"Стартовая ставка",""),IF(Z5="","Начало аукциона",""),IF(AA5="","Окончание аукциона",""),IF(AND(W5<>"",X5<>"",X5>W5),"Минимальная цена выше «Продать сейчас»",""),IF(AND(W5<>"",X5<>"",X5<=W5,X5>W5*0.9),"Минимальная цена выше 90% от «Продать сейчас»",""),IF(AND(W5<>"",Y5<>"",Y5>W5*0.3),"Стартовая ставка выше 30% от «Продать сейчас»",""),IF(AND(Z5<>"",AA5<>"",AA5<EDATE(Z5,3)+15),"Аукцион короче 3 месяцев и 15 дней",""),IF(AND(AB5="Да",OR(AC5="",AC5<=0)),"Цена тест-драйва за сутки",""),IF(OR(AJ5="",AJ5="Нет"),"Право собственности",""),IF(OR(AK5="",AK5="Нет"),"Справка об отсутствии обременений",""))="","",TEXTJOIN(", ",TRUE,IF(B5="","Название",""),IF(C5="","Тип недвижимости",""),IF(D5="","Страна",""),IF(E5="","Город",""),IF(F5="","Улица",""),IF(I5="","Валюта",""),IF(OR(AE5="",AE5<1),"Хотя бы 1 фото",""),IF(AND(OR(C5="Квартира",C5="Апартаменты",C5="Дом",C5="Вилла",C5="Коммерческая"),J5=""),"Площадь",""),IF(AND(OR(C5="Квартира",C5="Апартаменты"),K5=""),"Жилая площадь",""),IF(AND(OR(C5="Дом",C5="Вилла",C5="Земля"),L5=""),"Площадь участка",""),IF(AND(OR(C5="Квартира",C5="Апартаменты"),M5=""),"Комнаты",""),IF(AND(OR(C5="Дом",C5="Вилла"),N5=""),"Спальни",""),IF(AND(OR(C5="Квартира",C5="Апартаменты",C5="Дом",C5="Вилла"),O5=""),"Ванные",""),IF(AND(OR(C5="Квартира",C5="Апартаменты"),P5=""),"Этаж",""),IF(AND(OR(OR(C5="Квартира",C5="Апартаменты"),OR(C5="Дом",C5="Вилла")),Q5=""),"Этажей",""),IF(AND(OR(OR(C5="Квартира",C5="Апартаменты"),OR(C5="Дом",C5="Вилла")),OR(R5="",R5>YEAR(TODAY()))),"Год постройки",""),IF(AND(P5<>"",Q5<>"",P5>Q5),"Этаж больше этажности",""),IF(AND(OR(C5="Квартира",C5="Апартаменты",C5="Дом",C5="Вилла"),S5=""),"Материал",""),IF(AND(OR(C5="Коммерческая"),U5=""),"Тип коммерции",""),IF(AND(OR(C5="Земля"),V5=""),"Назначение земли",""),IF(OR(W5="",W5<=0),"Продать сейчас",""),IF(OR(X5="",X5<=0),"Минимальная цена продажи",""),IF(OR(Y5="",Y5<=0),"Стартовая ставка",""),IF(Z5="","Начало аукциона",""),IF(AA5="","Окончание аукциона",""),IF(AND(W5<>"",X5<>"",X5>W5),"Минимальная цена выше «Продать сейчас»",""),IF(AND(W5<>"",X5<>"",X5<=W5,X5>W5*0.9),"Минимальная цена выше 90% от «Продать сейчас»",""),IF(AND(W5<>"",Y5<>"",Y5>W5*0.3),"Стартовая ставка выше 30% от «Продать сейчас»",""),IF(AND(Z5<>"",AA5<>"",AA5<EDATE(Z5,3)+15),"Аукцион короче 3 месяцев и 15 дней",""),IF(AND(AB5="Да",OR(AC5="",AC5<=0)),"Цена тест-драйва за сутки",""),IF(OR(AJ5="",AJ5="Нет"),"Право собственности",""),IF(OR(AK5="",AK5="Нет"),"Справка об отсутствии обременений","")))) | AN5: =IF(NOT(COUNTA(A5:AL5)>0),"",IF(TEXTJOIN(", ",TRUE,IF(AH5="","Описание",""),IF(AND(AE5<>"",AE5>=1,AE5<5),"Фото меньше 5",""),IF(AG5="","Видео",""),IF(H5="","Кадастровый номер",""),IF(AF5="","Ссылка на фото",""))="","",TEXTJOIN(", ",TRUE,IF(AH5="","Описание",""),IF(AND(AE5<>"",AE5>=1,AE5<5),"Фото меньше 5",""),IF(AG5="","Видео",""),IF(H5="","Кадастровый номер",""),IF(AF5="","Ссылка на фото","")))) | AO5: =IF(NOT(COUNTA(A5:AL5)>0),"",IF(AM5="","Можно публиковать","Не хватает"))
AM6: =IF(NOT(COUNTA(A6:AL6)>0),"",IF(TEXTJOIN(", ",TRUE,IF(B6="","Название",""),IF(C6="","Тип недвижимости",""),IF(D6="","Страна",""),IF(E6="","Город",""),IF(F6="","Улица",""),IF(I6="","Валюта",""),IF(OR(AE6="",AE6<1),"Хотя бы 1 фото",""),IF(AND(OR(C6="Квартира",C6="Апартаменты",C6="Дом",C6="Вилла",C6="Коммерческая"),J6=""),"Площадь",""),IF(AND(OR(C6="Квартира",C6="Апартаменты"),K6=""),"Жилая площадь",""),IF(AND(OR(C6="Дом",C6="Вилла",C6="Земля"),L6=""),"Площадь участка",""),IF(AND(OR(C6="Квартира",C6="Апартаменты"),M6=""),"Комнаты",""),IF(AND(OR(C6="Дом",C6="Вилла"),N6=""),"Спальни",""),IF(AND(OR(C6="Квартира",C6="Апартаменты",C6="Дом",C6="Вилла"),O6=""),"Ванные",""),IF(AND(OR(C6="Квартира",C6="Апартаменты"),P6=""),"Этаж",""),IF(AND(OR(OR(C6="Квартира",C6="Апартаменты"),OR(C6="Дом",C6="Вилла")),Q6=""),"Этажей",""),IF(AND(OR(OR(C6="Квартира",C6="Апартаменты"),OR(C6="Дом",C6="Вилла")),OR(R6="",R6>YEAR(TODAY()))),"Год постройки",""),IF(AND(P6<>"",Q6<>"",P6>Q6),"Этаж больше этажности",""),IF(AND(OR(C6="Квартира",C6="Апартаменты",C6="Дом",C6="Вилла"),S6=""),"Материал",""),IF(AND(OR(C6="Коммерческая"),U6=""),"Тип коммерции",""),IF(AND(OR(C6="Земля"),V6=""),"Назначение земли",""),IF(OR(W6="",W6<=0),"Продать сейчас",""),IF(OR(X6="",X6<=0),"Минимальная цена продажи",""),IF(OR(Y6="",Y6<=0),"Стартовая ставка",""),IF(Z6="","Начало аукциона",""),IF(AA6="","Окончание аукциона",""),IF(AND(W6<>"",X6<>"",X6>W6),"Минимальная цена выше «Продать сейчас»",""),IF(AND(W6<>"",X6<>"",X6<=W6,X6>W6*0.9),"Минимальная цена выше 90% от «Продать сейчас»",""),IF(AND(W6<>"",Y6<>"",Y6>W6*0.3),"Стартовая ставка выше 30% от «Продать сейчас»",""),IF(AND(Z6<>"",AA6<>"",AA6<EDATE(Z6,3)+15),"Аукцион короче 3 месяцев и 15 дней",""),IF(AND(AB6="Да",OR(AC6="",AC6<=0)),"Цена тест-драйва за сутки",""),IF(OR(AJ6="",AJ6="Нет"),"Право собственности",""),IF(OR(AK6="",AK6="Нет"),"Справка об отсутствии обременений",""))="","",TEXTJOIN(", ",TRUE,IF(B6="","Название",""),IF(C6="","Тип недвижимости",""),IF(D6="","Страна",""),IF(E6="","Город",""),IF(F6="","Улица",""),IF(I6="","Валюта",""),IF(OR(AE6="",AE6<1),"Хотя бы 1 фото",""),IF(AND(OR(C6="Квартира",C6="Апартаменты",C6="Дом",C6="Вилла",C6="Коммерческая"),J6=""),"Площадь",""),IF(AND(OR(C6="Квартира",C6="Апартаменты"),K6=""),"Жилая площадь",""),IF(AND(OR(C6="Дом",C6="Вилла",C6="Земля"),L6=""),"Площадь участка",""),IF(AND(OR(C6="Квартира",C6="Апартаменты"),M6=""),"Комнаты",""),IF(AND(OR(C6="Дом",C6="Вилла"),N6=""),"Спальни",""),IF(AND(OR(C6="Квартира",C6="Апартаменты",C6="Дом",C6="Вилла"),O6=""),"Ванные",""),IF(AND(OR(C6="Квартира",C6="Апартаменты"),P6=""),"Этаж",""),IF(AND(OR(OR(C6="Квартира",C6="Апартаменты"),OR(C6="Дом",C6="Вилла")),Q6=""),"Этажей",""),IF(AND(OR(OR(C6="Квартира",C6="Апартаменты"),OR(C6="Дом",C6="Вилла")),OR(R6="",R6>YEAR(TODAY()))),"Год постройки",""),IF(AND(P6<>"",Q6<>"",P6>Q6),"Этаж больше этажности",""),IF(AND(OR(C6="Квартира",C6="Апартаменты",C6="Дом",C6="Вилла"),S6=""),"Материал",""),IF(AND(OR(C6="Коммерческая"),U6=""),"Тип коммерции",""),IF(AND(OR(C6="Земля"),V6=""),"Назначение земли",""),IF(OR(W6="",W6<=0),"Продать сейчас",""),IF(OR(X6="",X6<=0),"Минимальная цена продажи",""),IF(OR(Y6="",Y6<=0),"Стартовая ставка",""),IF(Z6="","Начало аукциона",""),IF(AA6="","Окончание аукциона",""),IF(AND(W6<>"",X6<>"",X6>W6),"Минимальная цена выше «Продать сейчас»",""),IF(AND(W6<>"",X6<>"",X6<=W6,X6>W6*0.9),"Минимальная цена выше 90% от «Продать сейчас»",""),IF(AND(W6<>"",Y6<>"",Y6>W6*0.3),"Стартовая ставка выше 30% от «Продать сейчас»",""),IF(AND(Z6<>"",AA6<>"",AA6<EDATE(Z6,3)+15),"Аукцион короче 3 месяцев и 15 дней",""),IF(AND(AB6="Да",OR(AC6="",AC6<=0)),"Цена тест-драйва за сутки",""),IF(OR(AJ6="",AJ6="Нет"),"Право собственности",""),IF(OR(AK6="",AK6="Нет"),"Справка об отсутствии обременений","")))) | AN6: =IF(NOT(COUNTA(A6:AL6)>0),"",IF(TEXTJOIN(", ",TRUE,IF(AH6="","Описание",""),IF(AND(AE6<>"",AE6>=1,AE6<5),"Фото меньше 5",""),IF(AG6="","Видео",""),IF(H6="","Кадастровый номер",""),IF(AF6="","Ссылка на фото",""))="","",TEXTJOIN(", ",TRUE,IF(AH6="","Описание",""),IF(AND(AE6<>"",AE6>=1,AE6<5),"Фото меньше 5",""),IF(AG6="","Видео",""),IF(H6="","Кадастровый номер",""),IF(AF6="","Ссылка на фото","")))) | AO6: =IF(NOT(COUNTA(A6:AL6)>0),"",IF(AM6="","Можно публиковать","Не хватает"))
AM7: =IF(NOT(COUNTA(A7:AL7)>0),"",IF(TEXTJOIN(", ",TRUE,IF(B7="","Название",""),IF(C7="","Тип недвижимости",""),IF(D7="","Страна",""),IF(E7="","Город",""),IF(F7="","Улица",""),IF(I7="","Валюта",""),IF(OR(AE7="",AE7<1),"Хотя бы 1 фото",""),IF(AND(OR(C7="Квартира",C7="Апартаменты",C7="Дом",C7="Вилла",C7="Коммерческая"),J7=""),"Площадь",""),IF(AND(OR(C7="Квартира",C7="Апартаменты"),K7=""),"Жилая площадь",""),IF(AND(OR(C7="Дом",C7="Вилла",C7="Земля"),L7=""),"Площадь участка",""),IF(AND(OR(C7="Квартира",C7="Апартаменты"),M7=""),"Комнаты",""),IF(AND(OR(C7="Дом",C7="Вилла"),N7=""),"Спальни",""),IF(AND(OR(C7="Квартира",C7="Апартаменты",C7="Дом",C7="Вилла"),O7=""),"Ванные",""),IF(AND(OR(C7="Квартира",C7="Апартаменты"),P7=""),"Этаж",""),IF(AND(OR(OR(C7="Квартира",C7="Апартаменты"),OR(C7="Дом",C7="Вилла")),Q7=""),"Этажей",""),IF(AND(OR(OR(C7="Квартира",C7="Апартаменты"),OR(C7="Дом",C7="Вилла")),OR(R7="",R7>YEAR(TODAY()))),"Год постройки",""),IF(AND(P7<>"",Q7<>"",P7>Q7),"Этаж больше этажности",""),IF(AND(OR(C7="Квартира",C7="Апартаменты",C7="Дом",C7="Вилла"),S7=""),"Материал",""),IF(AND(OR(C7="Коммерческая"),U7=""),"Тип коммерции",""),IF(AND(OR(C7="Земля"),V7=""),"Назначение земли",""),IF(OR(W7="",W7<=0),"Продать сейчас",""),IF(OR(X7="",X7<=0),"Минимальная цена продажи",""),IF(OR(Y7="",Y7<=0),"Стартовая ставка",""),IF(Z7="","Начало аукциона",""),IF(AA7="","Окончание аукциона",""),IF(AND(W7<>"",X7<>"",X7>W7),"Минимальная цена выше «Продать сейчас»",""),IF(AND(W7<>"",X7<>"",X7<=W7,X7>W7*0.9),"Минимальная цена выше 90% от «Продать сейчас»",""),IF(AND(W7<>"",Y7<>"",Y7>W7*0.3),"Стартовая ставка выше 30% от «Продать сейчас»",""),IF(AND(Z7<>"",AA7<>"",AA7<EDATE(Z7,3)+15),"Аукцион короче 3 месяцев и 15 дней",""),IF(AND(AB7="Да",OR(AC7="",AC7<=0)),"Цена тест-драйва за сутки",""),IF(OR(AJ7="",AJ7="Нет"),"Право собственности",""),IF(OR(AK7="",AK7="Нет"),"Справка об отсутствии обременений",""))="","",TEXTJOIN(", ",TRUE,IF(B7="","Название",""),IF(C7="","Тип недвижимости",""),IF(D7="","Страна",""),IF(E7="","Город",""),IF(F7="","Улица",""),IF(I7="","Валюта",""),IF(OR(AE7="",AE7<1),"Хотя бы 1 фото",""),IF(AND(OR(C7="Квартира",C7="Апартаменты",C7="Дом",C7="Вилла",C7="Коммерческая"),J7=""),"Площадь",""),IF(AND(OR(C7="Квартира",C7="Апартаменты"),K7=""),"Жилая площадь",""),IF(AND(OR(C7="Дом",C7="Вилла",C7="Земля"),L7=""),"Площадь участка",""),IF(AND(OR(C7="Квартира",C7="Апартаменты"),M7=""),"Комнаты",""),IF(AND(OR(C7="Дом",C7="Вилла"),N7=""),"Спальни",""),IF(AND(OR(C7="Квартира",C7="Апартаменты",C7="Дом",C7="Вилла"),O7=""),"Ванные",""),IF(AND(OR(C7="Квартира",C7="Апартаменты"),P7=""),"Этаж",""),IF(AND(OR(OR(C7="Квартира",C7="Апартаменты"),OR(C7="Дом",C7="Вилла")),Q7=""),"Этажей",""),IF(AND(OR(OR(C7="Квартира",C7="Апартаменты"),OR(C7="Дом",C7="Вилла")),OR(R7="",R7>YEAR(TODAY()))),"Год постройки",""),IF(AND(P7<>"",Q7<>"",P7>Q7),"Этаж больше этажности",""),IF(AND(OR(C7="Квартира",C7="Апартаменты",C7="Дом",C7="Вилла"),S7=""),"Материал",""),IF(AND(OR(C7="Коммерческая"),U7=""),"Тип коммерции",""),IF(AND(OR(C7="Земля"),V7=""),"Назначение земли",""),IF(OR(W7="",W7<=0),"Продать сейчас",""),IF(OR(X7="",X7<=0),"Минимальная цена продажи",""),IF(OR(Y7="",Y7<=0),"Стартовая ставка",""),IF(Z7="","Начало аукциона",""),IF(AA7="","Окончание аукциона",""),IF(AND(W7<>"",X7<>"",X7>W7),"Минимальная цена выше «Продать сейчас»",""),IF(AND(W7<>"",X7<>"",X7<=W7,X7>W7*0.9),"Минимальная цена выше 90% от «Продать сейчас»",""),IF(AND(W7<>"",Y7<>"",Y7>W7*0.3),"Стартовая ставка выше 30% от «Продать сейчас»",""),IF(AND(Z7<>"",AA7<>"",AA7<EDATE(Z7,3)+15),"Аукцион короче 3 месяцев и 15 дней",""),IF(AND(AB7="Да",OR(AC7="",AC7<=0)),"Цена тест-драйва за сутки",""),IF(OR(AJ7="",AJ7="Нет"),"Право собственности",""),IF(OR(AK7="",AK7="Нет"),"Справка об отсутствии обременений","")))) | AN7: =IF(NOT(COUNTA(A7:AL7)>0),"",IF(TEXTJOIN(", ",TRUE,IF(AH7="","Описание",""),IF(AND(AE7<>"",AE7>=1,AE7<5),"Фото меньше 5",""),IF(AG7="","Видео",""),IF(H7="","Кадастровый номер",""),IF(AF7="","Ссылка на фото",""))="","",TEXTJOIN(", ",TRUE,IF(AH7="","Описание",""),IF(AND(AE7<>"",AE7>=1,AE7<5),"Фото меньше 5",""),IF(AG7="","Видео",""),IF(H7="","Кадастровый номер",""),IF(AF7="","Ссылка на фото","")))) | AO7: =IF(NOT(COUNTA(A7:AL7)>0),"",IF(AM7="","Можно публиковать","Не хватает"))
AM8: =IF(NOT(COUNTA(A8:AL8)>0),"",IF(TEXTJOIN(", ",TRUE,IF(B8="","Название",""),IF(C8="","Тип недвижимости",""),IF(D8="","Страна",""),IF(E8="","Город",""),IF(F8="","Улица",""),IF(I8="","Валюта",""),IF(OR(AE8="",AE8<1),"Хотя бы 1 фото",""),IF(AND(OR(C8="Квартира",C8="Апартаменты",C8="Дом",C8="Вилла",C8="Коммерческая"),J8=""),"Площадь",""),IF(AND(OR(C8="Квартира",C8="Апартаменты"),K8=""),"Жилая площадь",""),IF(AND(OR(C8="Дом",C8="Вилла",C8="Земля"),L8=""),"Площадь участка",""),IF(AND(OR(C8="Квартира",C8="Апартаменты"),M8=""),"Комнаты",""),IF(AND(OR(C8="Дом",C8="Вилла"),N8=""),"Спальни",""),IF(AND(OR(C8="Квартира",C8="Апартаменты",C8="Дом",C8="Вилла"),O8=""),"Ванные",""),IF(AND(OR(C8="Квартира",C8="Апартаменты"),P8=""),"Этаж",""),IF(AND(OR(OR(C8="Квартира",C8="Апартаменты"),OR(C8="Дом",C8="Вилла")),Q8=""),"Этажей",""),IF(AND(OR(OR(C8="Квартира",C8="Апартаменты"),OR(C8="Дом",C8="Вилла")),OR(R8="",R8>YEAR(TODAY()))),"Год постройки",""),IF(AND(P8<>"",Q8<>"",P8>Q8),"Этаж больше этажности",""),IF(AND(OR(C8="Квартира",C8="Апартаменты",C8="Дом",C8="Вилла"),S8=""),"Материал",""),IF(AND(OR(C8="Коммерческая"),U8=""),"Тип коммерции",""),IF(AND(OR(C8="Земля"),V8=""),"Назначение земли",""),IF(OR(W8="",W8<=0),"Продать сейчас",""),IF(OR(X8="",X8<=0),"Минимальная цена продажи",""),IF(OR(Y8="",Y8<=0),"Стартовая ставка",""),IF(Z8="","Начало аукциона",""),IF(AA8="","Окончание аукциона",""),IF(AND(W8<>"",X8<>"",X8>W8),"Минимальная цена выше «Продать сейчас»",""),IF(AND(W8<>"",X8<>"",X8<=W8,X8>W8*0.9),"Минимальная цена выше 90% от «Продать сейчас»",""),IF(AND(W8<>"",Y8<>"",Y8>W8*0.3),"Стартовая ставка выше 30% от «Продать сейчас»",""),IF(AND(Z8<>"",AA8<>"",AA8<EDATE(Z8,3)+15),"Аукцион короче 3 месяцев и 15 дней",""),IF(AND(AB8="Да",OR(AC8="",AC8<=0)),"Цена тест-драйва за сутки",""),IF(OR(AJ8="",AJ8="Нет"),"Право собственности",""),IF(OR(AK8="",AK8="Нет"),"Справка об отсутствии обременений",""))="","",TEXTJOIN(", ",TRUE,IF(B8="","Название",""),IF(C8="","Тип недвижимости",""),IF(D8="","Страна",""),IF(E8="","Город",""),IF(F8="","Улица",""),IF(I8="","Валюта",""),IF(OR(AE8="",AE8<1),"Хотя бы 1 фото",""),IF(AND(OR(C8="Квартира",C8="Апартаменты",C8="Дом",C8="Вилла",C8="Коммерческая"),J8=""),"Площадь",""),IF(AND(OR(C8="Квартира",C8="Апартаменты"),K8=""),"Жилая площадь",""),IF(AND(OR(C8="Дом",C8="Вилла",C8="Земля"),L8=""),"Площадь участка",""),IF(AND(OR(C8="Квартира",C8="Апартаменты"),M8=""),"Комнаты",""),IF(AND(OR(C8="Дом",C8="Вилла"),N8=""),"Спальни",""),IF(AND(OR(C8="Квартира",C8="Апартаменты",C8="Дом",C8="Вилла"),O8=""),"Ванные",""),IF(AND(OR(C8="Квартира",C8="Апартаменты"),P8=""),"Этаж",""),IF(AND(OR(OR(C8="Квартира",C8="Апартаменты"),OR(C8="Дом",C8="Вилла")),Q8=""),"Этажей",""),IF(AND(OR(OR(C8="Квартира",C8="Апартаменты"),OR(C8="Дом",C8="Вилла")),OR(R8="",R8>YEAR(TODAY()))),"Год постройки",""),IF(AND(P8<>"",Q8<>"",P8>Q8),"Этаж больше этажности",""),IF(AND(OR(C8="Квартира",C8="Апартаменты",C8="Дом",C8="Вилла"),S8=""),"Материал",""),IF(AND(OR(C8="Коммерческая"),U8=""),"Тип коммерции",""),IF(AND(OR(C8="Земля"),V8=""),"Назначение земли",""),IF(OR(W8="",W8<=0),"Продать сейчас",""),IF(OR(X8="",X8<=0),"Минимальная цена продажи",""),IF(OR(Y8="",Y8<=0),"Стартовая ставка",""),IF(Z8="","Начало аукциона",""),IF(AA8="","Окончание аукциона",""),IF(AND(W8<>"",X8<>"",X8>W8),"Минимальная цена выше «Продать сейчас»",""),IF(AND(W8<>"",X8<>"",X8<=W8,X8>W8*0.9),"Минимальная цена выше 90% от «Продать сейчас»",""),IF(AND(W8<>"",Y8<>"",Y8>W8*0.3),"Стартовая ставка выше 30% от «Продать сейчас»",""),IF(AND(Z8<>"",AA8<>"",AA8<EDATE(Z8,3)+15),"Аукцион короче 3 месяцев и 15 дней",""),IF(AND(AB8="Да",OR(AC8="",AC8<=0)),"Цена тест-драйва за сутки",""),IF(OR(AJ8="",AJ8="Нет"),"Право собственности",""),IF(OR(AK8="",AK8="Нет"),"Справка об отсутствии обременений","")))) | AN8: =IF(NOT(COUNTA(A8:AL8)>0),"",IF(TEXTJOIN(", ",TRUE,IF(AH8="","Описание",""),IF(AND(AE8<>"",AE8>=1,AE8<5),"Фото меньше 5",""),IF(AG8="","Видео",""),IF(H8="","Кадастровый номер",""),IF(AF8="","Ссылка на фото",""))="","",TEXTJOIN(", ",TRUE,IF(AH8="","Описание",""),IF(AND(AE8<>"",AE8>=1,AE8<5),"Фото меньше 5",""),IF(AG8="","Видео",""),IF(H8="","Кадастровый номер",""),IF(AF8="","Ссылка на фото","")))) | AO8: =IF(NOT(COUNTA(A8:AL8)>0),"",IF(AM8="","Можно публиковать","Не хватает"))
AM9: =IF(NOT(COUNTA(A9:AL9)>0),"",IF(TEXTJOIN(", ",TRUE,IF(B9="","Название",""),IF(C9="","Тип недвижимости",""),IF(D9="","Страна",""),IF(E9="","Город",""),IF(F9="","Улица",""),IF(I9="","Валюта",""),IF(OR(AE9="",AE9<1),"Хотя бы 1 фото",""),IF(AND(OR(C9="Квартира",C9="Апартаменты",C9="Дом",C9="Вилла",C9="Коммерческая"),J9=""),"Площадь",""),IF(AND(OR(C9="Квартира",C9="Апартаменты"),K9=""),"Жилая площадь",""),IF(AND(OR(C9="Дом",C9="Вилла",C9="Земля"),L9=""),"Площадь участка",""),IF(AND(OR(C9="Квартира",C9="Апартаменты"),M9=""),"Комнаты",""),IF(AND(OR(C9="Дом",C9="Вилла"),N9=""),"Спальни",""),IF(AND(OR(C9="Квартира",C9="Апартаменты",C9="Дом",C9="Вилла"),O9=""),"Ванные",""),IF(AND(OR(C9="Квартира",C9="Апартаменты"),P9=""),"Этаж",""),IF(AND(OR(OR(C9="Квартира",C9="Апартаменты"),OR(C9="Дом",C9="Вилла")),Q9=""),"Этажей",""),IF(AND(OR(OR(C9="Квартира",C9="Апартаменты"),OR(C9="Дом",C9="Вилла")),OR(R9="",R9>YEAR(TODAY()))),"Год постройки",""),IF(AND(P9<>"",Q9<>"",P9>Q9),"Этаж больше этажности",""),IF(AND(OR(C9="Квартира",C9="Апартаменты",C9="Дом",C9="Вилла"),S9=""),"Материал",""),IF(AND(OR(C9="Коммерческая"),U9=""),"Тип коммерции",""),IF(AND(OR(C9="Земля"),V9=""),"Назначение земли",""),IF(OR(W9="",W9<=0),"Продать сейчас",""),IF(OR(X9="",X9<=0),"Минимальная цена продажи",""),IF(OR(Y9="",Y9<=0),"Стартовая ставка",""),IF(Z9="","Начало аукциона",""),IF(AA9="","Окончание аукциона",""),IF(AND(W9<>"",X9<>"",X9>W9),"Минимальная цена выше «Продать сейчас»",""),IF(AND(W9<>"",X9<>"",X9<=W9,X9>W9*0.9),"Минимальная цена выше 90% от «Продать сейчас»",""),IF(AND(W9<>"",Y9<>"",Y9>W9*0.3),"Стартовая ставка выше 30% от «Продать сейчас»",""),IF(AND(Z9<>"",AA9<>"",AA9<EDATE(Z9,3)+15),"Аукцион короче 3 месяцев и 15 дней",""),IF(AND(AB9="Да",OR(AC9="",AC9<=0)),"Цена тест-драйва за сутки",""),IF(OR(AJ9="",AJ9="Нет"),"Право собственности",""),IF(OR(AK9="",AK9="Нет"),"Справка об отсутствии обременений",""))="","",TEXTJOIN(", ",TRUE,IF(B9="","Название",""),IF(C9="","Тип недвижимости",""),IF(D9="","Страна",""),IF(E9="","Город",""),IF(F9="","Улица",""),IF(I9="","Валюта",""),IF(OR(AE9="",AE9<1),"Хотя бы 1 фото",""),IF(AND(OR(C9="Квартира",C9="Апартаменты",C9="Дом",C9="Вилла",C9="Коммерческая"),J9=""),"Площадь",""),IF(AND(OR(C9="Квартира",C9="Апартаменты"),K9=""),"Жилая площадь",""),IF(AND(OR(C9="Дом",C9="Вилла",C9="Земля"),L9=""),"Площадь участка",""),IF(AND(OR(C9="Квартира",C9="Апартаменты"),M9=""),"Комнаты",""),IF(AND(OR(C9="Дом",C9="Вилла"),N9=""),"Спальни",""),IF(AND(OR(C9="Квартира",C9="Апартаменты",C9="Дом",C9="Вилла"),O9=""),"Ванные",""),IF(AND(OR(C9="Квартира",C9="Апартаменты"),P9=""),"Этаж",""),IF(AND(OR(OR(C9="Квартира",C9="Апартаменты"),OR(C9="Дом",C9="Вилла")),Q9=""),"Этажей",""),IF(AND(OR(OR(C9="Квартира",C9="Апартаменты"),OR(C9="Дом",C9="Вилла")),OR(R9="",R9>YEAR(TODAY()))),"Год постройки",""),IF(AND(P9<>"",Q9<>"",P9>Q9),"Этаж больше этажности",""),IF(AND(OR(C9="Квартира",C9="Апартаменты",C9="Дом",C9="Вилла"),S9=""),"Материал",""),IF(AND(OR(C9="Коммерческая"),U9=""),"Тип коммерции",""),IF(AND(OR(C9="Земля"),V9=""),"Назначение земли",""),IF(OR(W9="",W9<=0),"Продать сейчас",""),IF(OR(X9="",X9<=0),"Минимальная цена продажи",""),IF(OR(Y9="",Y9<=0),"Стартовая ставка",""),IF(Z9="","Начало аукциона",""),IF(AA9="","Окончание аукциона",""),IF(AND(W9<>"",X9<>"",X9>W9),"Минимальная цена выше «Продать сейчас»",""),IF(AND(W9<>"",X9<>"",X9<=W9,X9>W9*0.9),"Минимальная цена выше 90% от «Продать сейчас»",""),IF(AND(W9<>"",Y9<>"",Y9>W9*0.3),"Стартовая ставка выше 30% от «Продать сейчас»",""),IF(AND(Z9<>"",AA9<>"",AA9<EDATE(Z9,3)+15),"Аукцион короче 3 месяцев и 15 дней",""),IF(AND(AB9="Да",OR(AC9="",AC9<=0)),"Цена тест-драйва за сутки",""),IF(OR(AJ9="",AJ9="Нет"),"Право собственности",""),IF(OR(AK9="",AK9="Нет"),"Справка об отсутствии обременений","")))) | AN9: =IF(NOT(COUNTA(A9:AL9)>0),"",IF(TEXTJOIN(", ",TRUE,IF(AH9="","Описание",""),IF(AND(AE9<>"",AE9>=1,AE9<5),"Фото меньше 5",""),IF(AG9="","Видео",""),IF(H9="","Кадастровый номер",""),IF(AF9="","Ссылка на фото",""))="","",TEXTJOIN(", ",TRUE,IF(AH9="","Описание",""),IF(AND(AE9<>"",AE9>=1,AE9<5),"Фото меньше 5",""),IF(AG9="","Видео",""),IF(H9="","Кадастровый номер",""),IF(AF9="","Ссылка на фото","")))) | AO9: =IF(NOT(COUNTA(A9:AL9)>0),"",IF(AM9="","Можно публиковать","Не хватает"))
AM10: =IF(NOT(COUNTA(A10:AL10)>0),"",IF(TEXTJOIN(", ",TRUE,IF(B10="","Название",""),IF(C10="","Тип недвижимости",""),IF(D10="","Страна",""),IF(E10="","Город",""),IF(F10="","Улица",""),IF(I10="","Валюта",""),IF(OR(AE10="",AE10<1),"Хотя бы 1 фото",""),IF(AND(OR(C10="Квартира",C10="Апартаменты",C10="Дом",C10="Вилла",C10="Коммерческая"),J10=""),"Площадь",""),IF(AND(OR(C10="Квартира",C10="Апартаменты"),K10=""),"Жилая площадь",""),IF(AND(OR(C10="Дом",C10="Вилла",C10="Земля"),L10=""),"Площадь участка",""),IF(AND(OR(C10="Квартира",C10="Апартаменты"),M10=""),"Комнаты",""),IF(AND(OR(C10="Дом",C10="Вилла"),N10=""),"Спальни",""),IF(AND(OR(C10="Квартира",C10="Апартаменты",C10="Дом",C10="Вилла"),O10=""),"Ванные",""),IF(AND(OR(C10="Квартира",C10="Апартаменты"),P10=""),"Этаж",""),IF(AND(OR(OR(C10="Квартира",C10="Апартаменты"),OR(C10="Дом",C10="Вилла")),Q10=""),"Этажей",""),IF(AND(OR(OR(C10="Квартира",C10="Апартаменты"),OR(C10="Дом",C10="Вилла")),OR(R10="",R10>YEAR(TODAY()))),"Год постройки",""),IF(AND(P10<>"",Q10<>"",P10>Q10),"Этаж больше этажности",""),IF(AND(OR(C10="Квартира",C10="Апартаменты",C10="Дом",C10="Вилла"),S10=""),"Материал",""),IF(AND(OR(C10="Коммерческая"),U10=""),"Тип коммерции",""),IF(AND(OR(C10="Земля"),V10=""),"Назначение земли",""),IF(OR(W10="",W10<=0),"Продать сейчас",""),IF(OR(X10="",X10<=0),"Минимальная цена продажи",""),IF(OR(Y10="",Y10<=0),"Стартовая ставка",""),IF(Z10="","Начало аукциона",""),IF(AA10="","Окончание аукциона",""),IF(AND(W10<>"",X10<>"",X10>W10),"Минимальная цена выше «Продать сейчас»",""),IF(AND(W10<>"",X10<>"",X10<=W10,X10>W10*0.9),"Минимальная цена выше 90% от «Продать сейчас»",""),IF(AND(W10<>"",Y10<>"",Y10>W10*0.3),"Стартовая ставка выше 30% от «Продать сейчас»",""),IF(AND(Z10<>"",AA10<>"",AA10<EDATE(Z10,3)+15),"Аукцион короче 3 месяцев и 15 дней",""),IF(AND(AB10="Да",OR(AC10="",AC10<=0)),"Цена тест-драйва за сутки",""),IF(OR(AJ10="",AJ10="Нет"),"Право собственности",""),IF(OR(AK10="",AK10="Нет"),"Справка об отсутствии обременений",""))="","",TEXTJOIN(", ",TRUE,IF(B10="","Название",""),IF(C10="","Тип недвижимости",""),IF(D10="","Страна",""),IF(E10="","Город",""),IF(F10="","Улица",""),IF(I10="","Валюта",""),IF(OR(AE10="",AE10<1),"Хотя бы 1 фото",""),IF(AND(OR(C10="Квартира",C10="Апартаменты",C10="Дом",C10="Вилла",C10="Коммерческая"),J10=""),"Площадь",""),IF(AND(OR(C10="Квартира",C10="Апартаменты"),K10=""),"Жилая площадь",""),IF(AND(OR(C10="Дом",C10="Вилла",C10="Земля"),L10=""),"Площадь участка",""),IF(AND(OR(C10="Квартира",C10="Апартаменты"),M10=""),"Комнаты",""),IF(AND(OR(C10="Дом",C10="Вилла"),N10=""),"Спальни",""),IF(AND(OR(C10="Квартира",C10="Апартаменты",C10="Дом",C10="Вилла"),O10=""),"Ванные",""),IF(AND(OR(C10="Квартира",C10="Апартаменты"),P10=""),"Этаж",""),IF(AND(OR(OR(C10="Квартира",C10="Апартаменты"),OR(C10="Дом",C10="Вилла")),Q10=""),"Этажей",""),IF(AND(OR(OR(C10="Квартира",C10="Апартаменты"),OR(C10="Дом",C10="Вилла")),OR(R10="",R10>YEAR(TODAY()))),"Год постройки",""),IF(AND(P10<>"",Q10<>"",P10>Q10),"Этаж больше этажности",""),IF(AND(OR(C10="Квартира",C10="Апартаменты",C10="Дом",C10="Вилла"),S10=""),"Материал",""),IF(AND(OR(C10="Коммерческая"),U10=""),"Тип коммерции",""),IF(AND(OR(C10="Земля"),V10=""),"Назначение земли",""),IF(OR(W10="",W10<=0),"Продать сейчас",""),IF(OR(X10="",X10<=0),"Минимальная цена продажи",""),IF(OR(Y10="",Y10<=0),"Стартовая ставка",""),IF(Z10="","Начало аукциона",""),IF(AA10="","Окончание аукциона",""),IF(AND(W10<>"",X10<>"",X10>W10),"Минимальная цена выше «Продать сейчас»",""),IF(AND(W10<>"",X10<>"",X10<=W10,X10>W10*0.9),"Минимальная цена выше 90% от «Продать сейчас»",""),IF(AND(W10<>"",Y10<>"",Y10>W10*0.3),"Стартовая ставка выше 30% от «Продать сейчас»",""),IF(AND(Z10<>"",AA10<>"",AA10<EDATE(Z10,3)+15),"Аукцион короче 3 месяцев и 15 дней",""),IF(AND(AB10="Да",OR(AC10="",AC10<=0)),"Цена тест-драйва за сутки",""),IF(OR(AJ10="",AJ10="Нет"),"Право собственности",""),IF(OR(AK10="",AK10="Нет"),"Справка об отсутствии обременений","")))) | AN10: =IF(NOT(COUNTA(A10:AL10)>0),"",IF(TEXTJOIN(", ",TRUE,IF(AH10="","Описание",""),IF(AND(AE10<>"",AE10>=1,AE10<5),"Фото меньше 5",""),IF(AG10="","Видео",""),IF(H10="","Кадастровый номер",""),IF(AF10="","Ссылка на фото",""))="","",TEXTJOIN(", ",TRUE,IF(AH10="","Описание",""),IF(AND(AE10<>"",AE10>=1,AE10<5),"Фото меньше 5",""),IF(AG10="","Видео",""),IF(H10="","Кадастровый номер",""),IF(AF10="","Ссылка на фото","")))) | AO10: =IF(NOT(COUNTA(A10:AL10)>0),"",IF(AM10="","Можно публиковать","Не хватает"))
AM11: =IF(NOT(COUNTA(A11:AL11)>0),"",IF(TEXTJOIN(", ",TRUE,IF(B11="","Название",""),IF(C11="","Тип недвижимости",""),IF(D11="","Страна",""),IF(E11="","Город",""),IF(F11="","Улица",""),IF(I11="","Валюта",""),IF(OR(AE11="",AE11<1),"Хотя бы 1 фото",""),IF(AND(OR(C11="Квартира",C11="Апартаменты",C11="Дом",C11="Вилла",C11="Коммерческая"),J11=""),"Площадь",""),IF(AND(OR(C11="Квартира",C11="Апартаменты"),K11=""),"Жилая площадь",""),IF(AND(OR(C11="Дом",C11="Вилла",C11="Земля"),L11=""),"Площадь участка",""),IF(AND(OR(C11="Квартира",C11="Апартаменты"),M11=""),"Комнаты",""),IF(AND(OR(C11="Дом",C11="Вилла"),N11=""),"Спальни",""),IF(AND(OR(C11="Квартира",C11="Апартаменты",C11="Дом",C11="Вилла"),O11=""),"Ванные",""),IF(AND(OR(C11="Квартира",C11="Апартаменты"),P11=""),"Этаж",""),IF(AND(OR(OR(C11="Квартира",C11="Апартаменты"),OR(C11="Дом",C11="Вилла")),Q11=""),"Этажей",""),IF(AND(OR(OR(C11="Квартира",C11="Апартаменты"),OR(C11="Дом",C11="Вилла")),OR(R11="",R11>YEAR(TODAY()))),"Год постройки",""),IF(AND(P11<>"",Q11<>"",P11>Q11),"Этаж больше этажности",""),IF(AND(OR(C11="Квартира",C11="Апартаменты",C11="Дом",C11="Вилла"),S11=""),"Материал",""),IF(AND(OR(C11="Коммерческая"),U11=""),"Тип коммерции",""),IF(AND(OR(C11="Земля"),V11=""),"Назначение земли",""),IF(OR(W11="",W11<=0),"Продать сейчас",""),IF(OR(X11="",X11<=0),"Минимальная цена продажи",""),IF(OR(Y11="",Y11<=0),"Стартовая ставка",""),IF(Z11="","Начало аукциона",""),IF(AA11="","Окончание аукциона",""),IF(AND(W11<>"",X11<>"",X11>W11),"Минимальная цена выше «Продать сейчас»",""),IF(AND(W11<>"",X11<>"",X11<=W11,X11>W11*0.9),"Минимальная цена выше 90% от «Продать сейчас»",""),IF(AND(W11<>"",Y11<>"",Y11>W11*0.3),"Стартовая ставка выше 30% от «Продать сейчас»",""),IF(AND(Z11<>"",AA11<>"",AA11<EDATE(Z11,3)+15),"Аукцион короче 3 месяцев и 15 дней",""),IF(AND(AB11="Да",OR(AC11="",AC11<=0)),"Цена тест-драйва за сутки",""),IF(OR(AJ11="",AJ11="Нет"),"Право собственности",""),IF(OR(AK11="",AK11="Нет"),"Справка об отсутствии обременений",""))="","",TEXTJOIN(", ",TRUE,IF(B11="","Название",""),IF(C11="","Тип недвижимости",""),IF(D11="","Страна",""),IF(E11="","Город",""),IF(F11="","Улица",""),IF(I11="","Валюта",""),IF(OR(AE11="",AE11<1),"Хотя бы 1 фото",""),IF(AND(OR(C11="Квартира",C11="Апартаменты",C11="Дом",C11="Вилла",C11="Коммерческая"),J11=""),"Площадь",""),IF(AND(OR(C11="Квартира",C11="Апартаменты"),K11=""),"Жилая площадь",""),IF(AND(OR(C11="Дом",C11="Вилла",C11="Земля"),L11=""),"Площадь участка",""),IF(AND(OR(C11="Квартира",C11="Апартаменты"),M11=""),"Комнаты",""),IF(AND(OR(C11="Дом",C11="Вилла"),N11=""),"Спальни",""),IF(AND(OR(C11="Квартира",C11="Апартаменты",C11="Дом",C11="Вилла"),O11=""),"Ванные",""),IF(AND(OR(C11="Квартира",C11="Апартаменты"),P11=""),"Этаж",""),IF(AND(OR(OR(C11="Квартира",C11="Апартаменты"),OR(C11="Дом",C11="Вилла")),Q11=""),"Этажей",""),IF(AND(OR(OR(C11="Квартира",C11="Апартаменты"),OR(C11="Дом",C11="Вилла")),OR(R11="",R11>YEAR(TODAY()))),"Год постройки",""),IF(AND(P11<>"",Q11<>"",P11>Q11),"Этаж больше этажности",""),IF(AND(OR(C11="Квартира",C11="Апартаменты",C11="Дом",C11="Вилла"),S11=""),"Материал",""),IF(AND(OR(C11="Коммерческая"),U11=""),"Тип коммерции",""),IF(AND(OR(C11="Земля"),V11=""),"Назначение земли",""),IF(OR(W11="",W11<=0),"Продать сейчас",""),IF(OR(X11="",X11<=0),"Минимальная цена продажи",""),IF(OR(Y11="",Y11<=0),"Стартовая ставка",""),IF(Z11="","Начало аукциона",""),IF(AA11="","Окончание аукциона",""),IF(AND(W11<>"",X11<>"",X11>W11),"Минимальная цена выше «Продать сейчас»",""),IF(AND(W11<>"",X11<>"",X11<=W11,X11>W11*0.9),"Минимальная цена выше 90% от «Продать сейчас»",""),IF(AND(W11<>"",Y11<>"",Y11>W11*0.3),"Стартовая ставка выше 30% от «Продать сейчас»",""),IF(AND(Z11<>"",AA11<>"",AA11<EDATE(Z11,3)+15),"Аукцион короче 3 месяцев и 15 дней",""),IF(AND(AB11="Да",OR(AC11="",AC11<=0)),"Цена тест-драйва за сутки",""),IF(OR(AJ11="",AJ11="Нет"),"Право собственности",""),IF(OR(AK11="",AK11="Нет"),"Справка об отсутствии обременений","")))) | AN11: =IF(NOT(COUNTA(A11:AL11)>0),"",IF(TEXTJOIN(", ",TRUE,IF(AH11="","Описание",""),IF(AND(AE11<>"",AE11>=1,AE11<5),"Фото меньше 5",""),IF(AG11="","Видео",""),IF(H11="","Кадастровый номер",""),IF(AF11="","Ссылка на фото",""))="","",TEXTJOIN(", ",TRUE,IF(AH11="","Описание",""),IF(AND(AE11<>"",AE11>=1,AE11<5),"Фото меньше 5",""),IF(AG11="","Видео",""),IF(H11="","Кадастровый номер",""),IF(AF11="","Ссылка на фото","")))) | AO11: =IF(NOT(COUNTA(A11:AL11)>0),"",IF(AM11="","Можно публиковать","Не хватает"))
AM12: =IF(NOT(COUNTA(A12:AL12)>0),"",IF(TEXTJOIN(", ",TRUE,IF(B12="","Название",""),IF(C12="","Тип недвижимости",""),IF(D12="","Страна",""),IF(E12="","Город",""),IF(F12="","Улица",""),IF(I12="","Валюта",""),IF(OR(AE12="",AE12<1),"Хотя бы 1 фото",""),IF(AND(OR(C12="Квартира",C12="Апартаменты",C12="Дом",C12="Вилла",C12="Коммерческая"),J12=""),"Площадь",""),IF(AND(OR(C12="Квартира",C12="Апартаменты"),K12=""),"Жилая площадь",""),IF(AND(OR(C12="Дом",C12="Вилла",C12="Земля"),L12=""),"Площадь участка",""),IF(AND(OR(C12="Квартира",C12="Апартаменты"),M12=""),"Комнаты",""),IF(AND(OR(C12="Дом",C12="Вилла"),N12=""),"Спальни",""),IF(AND(OR(C12="Квартира",C12="Апартаменты",C12="Дом",C12="Вилла"),O12=""),"Ванные",""),IF(AND(OR(C12="Квартира",C12="Апартаменты"),P12=""),"Этаж",""),IF(AND(OR(OR(C12="Квартира",C12="Апартаменты"),OR(C12="Дом",C12="Вилла")),Q12=""),"Этажей",""),IF(AND(OR(OR(C12="Квартира",C12="Апартаменты"),OR(C12="Дом",C12="Вилла")),OR(R12="",R12>YEAR(TODAY()))),"Год постройки",""),IF(AND(P12<>"",Q12<>"",P12>Q12),"Этаж больше этажности",""),IF(AND(OR(C12="Квартира",C12="Апартаменты",C12="Дом",C12="Вилла"),S12=""),"Материал",""),IF(AND(OR(C12="Коммерческая"),U12=""),"Тип коммерции",""),IF(AND(OR(C12="Земля"),V12=""),"Назначение земли",""),IF(OR(W12="",W12<=0),"Продать сейчас",""),IF(OR(X12="",X12<=0),"Минимальная цена продажи",""),IF(OR(Y12="",Y12<=0),"Стартовая ставка",""),IF(Z12="","Начало аукциона",""),IF(AA12="","Окончание аукциона",""),IF(AND(W12<>"",X12<>"",X12>W12),"Минимальная цена выше «Продать сейчас»",""),IF(AND(W12<>"",X12<>"",X12<=W12,X12>W12*0.9),"Минимальная цена выше 90% от «Продать сейчас»",""),IF(AND(W12<>"",Y12<>"",Y12>W12*0.3),"Стартовая ставка выше 30% от «Продать сейчас»",""),IF(AND(Z12<>"",AA12<>"",AA12<EDATE(Z12,3)+15),"Аукцион короче 3 месяцев и 15 дней",""),IF(AND(AB12="Да",OR(AC12="",AC12<=0)),"Цена тест-драйва за сутки",""),IF(OR(AJ12="",AJ12="Нет"),"Право собственности",""),IF(OR(AK12="",AK12="Нет"),"Справка об отсутствии обременений",""))="","",TEXTJOIN(", ",TRUE,IF(B12="","Название",""),IF(C12="","Тип недвижимости",""),IF(D12="","Страна",""),IF(E12="","Город",""),IF(F12="","Улица",""),IF(I12="","Валюта",""),IF(OR(AE12="",AE12<1),"Хотя бы 1 фото",""),IF(AND(OR(C12="Квартира",C12="Апартаменты",C12="Дом",C12="Вилла",C12="Коммерческая"),J12=""),"Площадь",""),IF(AND(OR(C12="Квартира",C12="Апартаменты"),K12=""),"Жилая площадь",""),IF(AND(OR(C12="Дом",C12="Вилла",C12="Земля"),L12=""),"Площадь участка",""),IF(AND(OR(C12="Квартира",C12="Апартаменты"),M12=""),"Комнаты",""),IF(AND(OR(C12="Дом",C12="Вилла"),N12=""),"Спальни",""),IF(AND(OR(C12="Квартира",C12="Апартаменты",C12="Дом",C12="Вилла"),O12=""),"Ванные",""),IF(AND(OR(C12="Квартира",C12="Апартаменты"),P12=""),"Этаж",""),IF(AND(OR(OR(C12="Квартира",C12="Апартаменты"),OR(C12="Дом",C12="Вилла")),Q12=""),"Этажей",""),IF(AND(OR(OR(C12="Квартира",C12="Апартаменты"),OR(C12="Дом",C12="Вилла")),OR(R12="",R12>YEAR(TODAY()))),"Год постройки",""),IF(AND(P12<>"",Q12<>"",P12>Q12),"Этаж больше этажности",""),IF(AND(OR(C12="Квартира",C12="Апартаменты",C12="Дом",C12="Вилла"),S12=""),"Материал",""),IF(AND(OR(C12="Коммерческая"),U12=""),"Тип коммерции",""),IF(AND(OR(C12="Земля"),V12=""),"Назначение земли",""),IF(OR(W12="",W12<=0),"Продать сейчас",""),IF(OR(X12="",X12<=0),"Минимальная цена продажи",""),IF(OR(Y12="",Y12<=0),"Стартовая ставка",""),IF(Z12="","Начало аукциона",""),IF(AA12="","Окончание аукциона",""),IF(AND(W12<>"",X12<>"",X12>W12),"Минимальная цена выше «Продать сейчас»",""),IF(AND(W12<>"",X12<>"",X12<=W12,X12>W12*0.9),"Минимальная цена выше 90% от «Продать сейчас»",""),IF(AND(W12<>"",Y12<>"",Y12>W12*0.3),"Стартовая ставка выше 30% от «Продать сейчас»",""),IF(AND(Z12<>"",AA12<>"",AA12<EDATE(Z12,3)+15),"Аукцион короче 3 месяцев и 15 дней",""),IF(AND(AB12="Да",OR(AC12="",AC12<=0)),"Цена тест-драйва за сутки",""),IF(OR(AJ12="",AJ12="Нет"),"Право собственности",""),IF(OR(AK12="",AK12="Нет"),"Справка об отсутствии обременений","")))) | AN12: =IF(NOT(COUNTA(A12:AL12)>0),"",IF(TEXTJOIN(", ",TRUE,IF(AH12="","Описание",""),IF(AND(AE12<>"",AE12>=1,AE12<5),"Фото меньше 5",""),IF(AG12="","Видео",""),IF(H12="","Кадастровый номер",""),IF(AF12="","Ссылка на фото",""))="","",TEXTJOIN(", ",TRUE,IF(AH12="","Описание",""),IF(AND(AE12<>"",AE12>=1,AE12<5),"Фото меньше 5",""),IF(AG12="","Видео",""),IF(H12="","Кадастровый номер",""),IF(AF12="","Ссылка на фото","")))) | AO12: =IF(NOT(COUNTA(A12:AL12)>0),"",IF(AM12="","Можно публиковать","Не хватает"))
AM13: =IF(NOT(COUNTA(A13:AL13)>0),"",IF(TEXTJOIN(", ",TRUE,IF(B13="","Название",""),IF(C13="","Тип недвижимости",""),IF(D13="","Страна",""),IF(E13="","Город",""),IF(F13="","Улица",""),IF(I13="","Валюта",""),IF(OR(AE13="",AE13<1),"Хотя бы 1 фото",""),IF(AND(OR(C13="Квартира",C13="Апартаменты",C13="Дом",C13="Вилла",C13="Коммерческая"),J13=""),"Площадь",""),IF(AND(OR(C13="Квартира",C13="Апартаменты"),K13=""),"Жилая площадь",""),IF(AND(OR(C13="Дом",C13="Вилла",C13="Земля"),L13=""),"Площадь участка",""),IF(AND(OR(C13="Квартира",C13="Апартаменты"),M13=""),"Комнаты",""),IF(AND(OR(C13="Дом",C13="Вилла"),N13=""),"Спальни",""),IF(AND(OR(C13="Квартира",C13="Апартаменты",C13="Дом",C13="Вилла"),O13=""),"Ванные",""),IF(AND(OR(C13="Квартира",C13="Апартаменты"),P13=""),"Этаж",""),IF(AND(OR(OR(C13="Квартира",C13="Апартаменты"),OR(C13="Дом",C13="Вилла")),Q13=""),"Этажей",""),IF(AND(OR(OR(C13="Квартира",C13="Апартаменты"),OR(C13="Дом",C13="Вилла")),OR(R13="",R13>YEAR(TODAY()))),"Год постройки",""),IF(AND(P13<>"",Q13<>"",P13>Q13),"Этаж больше этажности",""),IF(AND(OR(C13="Квартира",C13="Апартаменты",C13="Дом",C13="Вилла"),S13=""),"Материал",""),IF(AND(OR(C13="Коммерческая"),U13=""),"Тип коммерции",""),IF(AND(OR(C13="Земля"),V13=""),"Назначение земли",""),IF(OR(W13="",W13<=0),"Продать сейчас",""),IF(OR(X13="",X13<=0),"Минимальная цена продажи",""),IF(OR(Y13="",Y13<=0),"Стартовая ставка",""),IF(Z13="","Начало аукциона",""),IF(AA13="","Окончание аукциона",""),IF(AND(W13<>"",X13<>"",X13>W13),"Минимальная цена выше «Продать сейчас»",""),IF(AND(W13<>"",X13<>"",X13<=W13,X13>W13*0.9),"Минимальная цена выше 90% от «Продать сейчас»",""),IF(AND(W13<>"",Y13<>"",Y13>W13*0.3),"Стартовая ставка выше 30% от «Продать сейчас»",""),IF(AND(Z13<>"",AA13<>"",AA13<EDATE(Z13,3)+15),"Аукцион короче 3 месяцев и 15 дней",""),IF(AND(AB13="Да",OR(AC13="",AC13<=0)),"Цена тест-драйва за сутки",""),IF(OR(AJ13="",AJ13="Нет"),"Право собственности",""),IF(OR(AK13="",AK13="Нет"),"Справка об отсутствии обременений",""))="","",TEXTJOIN(", ",TRUE,IF(B13="","Название",""),IF(C13="","Тип недвижимости",""),IF(D13="","Страна",""),IF(E13="","Город",""),IF(F13="","Улица",""),IF(I13="","Валюта",""),IF(OR(AE13="",AE13<1),"Хотя бы 1 фото",""),IF(AND(OR(C13="Квартира",C13="Апартаменты",C13="Дом",C13="Вилла",C13="Коммерческая"),J13=""),"Площадь",""),IF(AND(OR(C13="Квартира",C13="Апартаменты"),K13=""),"Жилая площадь",""),IF(AND(OR(C13="Дом",C13="Вилла",C13="Земля"),L13=""),"Площадь участка",""),IF(AND(OR(C13="Квартира",C13="Апартаменты"),M13=""),"Комнаты",""),IF(AND(OR(C13="Дом",C13="Вилла"),N13=""),"Спальни",""),IF(AND(OR(C13="Квартира",C13="Апартаменты",C13="Дом",C13="Вилла"),O13=""),"Ванные",""),IF(AND(OR(C13="Квартира",C13="Апартаменты"),P13=""),"Этаж",""),IF(AND(OR(OR(C13="Квартира",C13="Апартаменты"),OR(C13="Дом",C13="Вилла")),Q13=""),"Этажей",""),IF(AND(OR(OR(C13="Квартира",C13="Апартаменты"),OR(C13="Дом",C13="Вилла")),OR(R13="",R13>YEAR(TODAY()))),"Год постройки",""),IF(AND(P13<>"",Q13<>"",P13>Q13),"Этаж больше этажности",""),IF(AND(OR(C13="Квартира",C13="Апартаменты",C13="Дом",C13="Вилла"),S13=""),"Материал",""),IF(AND(OR(C13="Коммерческая"),U13=""),"Тип коммерции",""),IF(AND(OR(C13="Земля"),V13=""),"Назначение земли",""),IF(OR(W13="",W13<=0),"Продать сейчас",""),IF(OR(X13="",X13<=0),"Минимальная цена продажи",""),IF(OR(Y13="",Y13<=0),"Стартовая ставка",""),IF(Z13="","Начало аукциона",""),IF(AA13="","Окончание аукциона",""),IF(AND(W13<>"",X13<>"",X13>W13),"Минимальная цена выше «Продать сейчас»",""),IF(AND(W13<>"",X13<>"",X13<=W13,X13>W13*0.9),"Минимальная цена выше 90% от «Продать сейчас»",""),IF(AND(W13<>"",Y13<>"",Y13>W13*0.3),"Стартовая ставка выше 30% от «Продать сейчас»",""),IF(AND(Z13<>"",AA13<>"",AA13<EDATE(Z13,3)+15),"Аукцион короче 3 месяцев и 15 дней",""),IF(AND(AB13="Да",OR(AC13="",AC13<=0)),"Цена тест-драйва за сутки",""),IF(OR(AJ13="",AJ13="Нет"),"Право собственности",""),IF(OR(AK13="",AK13="Нет"),"Справка об отсутствии обременений","")))) | AN13: =IF(NOT(COUNTA(A13:AL13)>0),"",IF(TEXTJOIN(", ",TRUE,IF(AH13="","Описание",""),IF(AND(AE13<>"",AE13>=1,AE13<5),"Фото меньше 5",""),IF(AG13="","Видео",""),IF(H13="","Кадастровый номер",""),IF(AF13="","Ссылка на фото",""))="","",TEXTJOIN(", ",TRUE,IF(AH13="","Описание",""),IF(AND(AE13<>"",AE13>=1,AE13<5),"Фото меньше 5",""),IF(AG13="","Видео",""),IF(H13="","Кадастровый номер",""),IF(AF13="","Ссылка на фото","")))) | AO13: =IF(NOT(COUNTA(A13:AL13)>0),"",IF(AM13="","Можно публиковать","Не хватает"))
AM14: =IF(NOT(COUNTA(A14:AL14)>0),"",IF(TEXTJOIN(", ",TRUE,IF(B14="","Название",""),IF(C14="","Тип недвижимости",""),IF(D14="","Страна",""),IF(E14="","Город",""),IF(F14="","Улица",""),IF(I14="","Валюта",""),IF(OR(AE14="",AE14<1),"Хотя бы 1 фото",""),IF(AND(OR(C14="Квартира",C14="Апартаменты",C14="Дом",C14="Вилла",C14="Коммерческая"),J14=""),"Площадь",""),IF(AND(OR(C14="Квартира",C14="Апартаменты"),K14=""),"Жилая площадь",""),IF(AND(OR(C14="Дом",C14="Вилла",C14="Земля"),L14=""),"Площадь участка",""),IF(AND(OR(C14="Квартира",C14="Апартаменты"),M14=""),"Комнаты",""),IF(AND(OR(C14="Дом",C14="Вилла"),N14=""),"Спальни",""),IF(AND(OR(C14="Квартира",C14="Апартаменты",C14="Дом",C14="Вилла"),O14=""),"Ванные",""),IF(AND(OR(C14="Квартира",C14="Апартаменты"),P14=""),"Этаж",""),IF(AND(OR(OR(C14="Квартира",C14="Апартаменты"),OR(C14="Дом",C14="Вилла")),Q14=""),"Этажей",""),IF(AND(OR(OR(C14="Квартира",C14="Апартаменты"),OR(C14="Дом",C14="Вилла")),OR(R14="",R14>YEAR(TODAY()))),"Год постройки",""),IF(AND(P14<>"",Q14<>"",P14>Q14),"Этаж больше этажности",""),IF(AND(OR(C14="Квартира",C14="Апартаменты",C14="Дом",C14="Вилла"),S14=""),"Материал",""),IF(AND(OR(C14="Коммерческая"),U14=""),"Тип коммерции",""),IF(AND(OR(C14="Земля"),V14=""),"Назначение земли",""),IF(OR(W14="",W14<=0),"Продать сейчас",""),IF(OR(X14="",X14<=0),"Минимальная цена продажи",""),IF(OR(Y14="",Y14<=0),"Стартовая ставка",""),IF(Z14="","Начало аукциона",""),IF(AA14="","Окончание аукциона",""),IF(AND(W14<>"",X14<>"",X14>W14),"Минимальная цена выше «Продать сейчас»",""),IF(AND(W14<>"",X14<>"",X14<=W14,X14>W14*0.9),"Минимальная цена выше 90% от «Продать сейчас»",""),IF(AND(W14<>"",Y14<>"",Y14>W14*0.3),"Стартовая ставка выше 30% от «Продать сейчас»",""),IF(AND(Z14<>"",AA14<>"",AA14<EDATE(Z14,3)+15),"Аукцион короче 3 месяцев и 15 дней",""),IF(AND(AB14="Да",OR(AC14="",AC14<=0)),"Цена тест-драйва за сутки",""),IF(OR(AJ14="",AJ14="Нет"),"Право собственности",""),IF(OR(AK14="",AK14="Нет"),"Справка об отсутствии обременений",""))="","",TEXTJOIN(", ",TRUE,IF(B14="","Название",""),IF(C14="","Тип недвижимости",""),IF(D14="","Страна",""),IF(E14="","Город",""),IF(F14="","Улица",""),IF(I14="","Валюта",""),IF(OR(AE14="",AE14<1),"Хотя бы 1 фото",""),IF(AND(OR(C14="Квартира",C14="Апартаменты",C14="Дом",C14="Вилла",C14="Коммерческая"),J14=""),"Площадь",""),IF(AND(OR(C14="Квартира",C14="Апартаменты"),K14=""),"Жилая площадь",""),IF(AND(OR(C14="Дом",C14="Вилла",C14="Земля"),L14=""),"Площадь участка",""),IF(AND(OR(C14="Квартира",C14="Апартаменты"),M14=""),"Комнаты",""),IF(AND(OR(C14="Дом",C14="Вилла"),N14=""),"Спальни",""),IF(AND(OR(C14="Квартира",C14="Апартаменты",C14="Дом",C14="Вилла"),O14=""),"Ванные",""),IF(AND(OR(C14="Квартира",C14="Апартаменты"),P14=""),"Этаж",""),IF(AND(OR(OR(C14="Квартира",C14="Апартаменты"),OR(C14="Дом",C14="Вилла")),Q14=""),"Этажей",""),IF(AND(OR(OR(C14="Квартира",C14="Апартаменты"),OR(C14="Дом",C14="Вилла")),OR(R14="",R14>YEAR(TODAY()))),"Год постройки",""),IF(AND(P14<>"",Q14<>"",P14>Q14),"Этаж больше этажности",""),IF(AND(OR(C14="Квартира",C14="Апартаменты",C14="Дом",C14="Вилла"),S14=""),"Материал",""),IF(AND(OR(C14="Коммерческая"),U14=""),"Тип коммерции",""),IF(AND(OR(C14="Земля"),V14=""),"Назначение земли",""),IF(OR(W14="",W14<=0),"Продать сейчас",""),IF(OR(X14="",X14<=0),"Минимальная цена продажи",""),IF(OR(Y14="",Y14<=0),"Стартовая ставка",""),IF(Z14="","Начало аукциона",""),IF(AA14="","Окончание аукциона",""),IF(AND(W14<>"",X14<>"",X14>W14),"Минимальная цена выше «Продать сейчас»",""),IF(AND(W14<>"",X14<>"",X14<=W14,X14>W14*0.9),"Минимальная цена выше 90% от «Продать сейчас»",""),IF(AND(W14<>"",Y14<>"",Y14>W14*0.3),"Стартовая ставка выше 30% от «Продать сейчас»",""),IF(AND(Z14<>"",AA14<>"",AA14<EDATE(Z14,3)+15),"Аукцион короче 3 месяцев и 15 дней",""),IF(AND(AB14="Да",OR(AC14="",AC14<=0)),"Цена тест-драйва за сутки",""),IF(OR(AJ14="",AJ14="Нет"),"Право собственности",""),IF(OR(AK14="",AK14="Нет"),"Справка об отсутствии обременений","")))) | AN14: =IF(NOT(COUNTA(A14:AL14)>0),"",IF(TEXTJOIN(", ",TRUE,IF(AH14="","Описание",""),IF(AND(AE14<>"",AE14>=1,AE14<5),"Фото меньше 5",""),IF(AG14="","Видео",""),IF(H14="","Кадастровый номер",""),IF(AF14="","Ссылка на фото",""))="","",TEXTJOIN(", ",TRUE,IF(AH14="","Описание",""),IF(AND(AE14<>"",AE14>=1,AE14<5),"Фото меньше 5",""),IF(AG14="","Видео",""),IF(H14="","Кадастровый номер",""),IF(AF14="","Ссылка на фото","")))) | AO14: =IF(NOT(COUNTA(A14:AL14)>0),"",IF(AM14="","Можно публиковать","Не хватает"))
